
// Find the location where the Promise.catch issue exists and modify it:

// Replace this pattern:
// somePromiseFunction().catch(err => { ... });

// With this pattern:
// somePromiseFunction().then(undefined, err => { ... });

// Or convert to async/await pattern:
// try {
//   await somePromiseFunction();
// } catch (err) {
//   // handle error
// }

// Example fix:
const handleSomething = async () => {
  try {
    await fetchData();
  } catch (err) {
    console.error('Error fetching data:', err);
  }
};

// Alternatively, if using .then()
const handlePromise = () => {
  fetchData().then(
    (result) => {
      // Success handler
    }, 
    (error) => {
      // Error handler - this replaces .catch()
      console.error('Error:', error);
    }
  );
};
